[32m2024-03-04 10:52:43 +0700[0m - dagster - [34mDEBUG[0m - __ASSET_JOB - daa15a82-259f-46c6-9df4-bec839bf3d05 - 30196 - LOGS_CAPTURED - Started capturing logs in process (pid: 30196).
[32m2024-03-04 10:52:43 +0700[0m - dagster - [34mDEBUG[0m - __ASSET_JOB - daa15a82-259f-46c6-9df4-bec839bf3d05 - 30196 - bronze__ecom__bronze_olist_orders_dataset - STEP_START - Started execution of step "bronze__ecom__bronze_olist_orders_dataset".
[32m2024-03-04 10:52:44 +0700[0m - dagster - [34mDEBUG[0m - __ASSET_JOB - daa15a82-259f-46c6-9df4-bec839bf3d05 - 30196 - bronze__ecom__bronze_olist_orders_dataset - STEP_OUTPUT - Yielded output "result" of type "DataFrame". (Type check passed).
[32m2024-03-04 10:52:44 +0700[0m - dagster - [34mERROR[0m - [31m__ASSET_JOB - daa15a82-259f-46c6-9df4-bec839bf3d05 - 30196 - bronze__ecom__bronze_olist_orders_dataset - STEP_FAILURE - Execution of step "bronze__ecom__bronze_olist_orders_dataset" failed.

dagster._core.errors.DagsterExecutionHandleOutputError: Error occurred while handling output "result" of step "bronze__ecom__bronze_olist_orders_dataset"::

OSError: Cannot save file into a non-existent directory: 'data'

Stack Trace:
  File "/home/cthi/PycharmProjects/fde-etl-pipeline/venv/lib/python3.8/site-packages/dagster/_core/execution/plan/utils.py", line 54, in op_execution_error_boundary
    yield
  File "/home/cthi/PycharmProjects/fde-etl-pipeline/venv/lib/python3.8/site-packages/dagster/_utils/__init__.py", line 467, in iterate_with_context
    next_output = next(iterator)
  File "/home/cthi/PycharmProjects/fde-etl-pipeline/venv/lib/python3.8/site-packages/dagster/_core/execution/plan/execute_step.py", line 792, in _gen_fn
    gen_output = output_manager.handle_output(output_context, output.value)
  File "/home/cthi/PycharmProjects/fde-etl-pipeline/resources/minio_io_manager.py", line 20, in handle_output
    obj.to_csv('data/df.csv')
  File "/home/cthi/PycharmProjects/fde-etl-pipeline/venv/lib/python3.8/site-packages/pandas/core/generic.py", line 3772, in to_csv
    return DataFrameRenderer(formatter).to_csv(
  File "/home/cthi/PycharmProjects/fde-etl-pipeline/venv/lib/python3.8/site-packages/pandas/io/formats/format.py", line 1186, in to_csv
    csv_formatter.save()
  File "/home/cthi/PycharmProjects/fde-etl-pipeline/venv/lib/python3.8/site-packages/pandas/io/formats/csvs.py", line 240, in save
    with get_handle(
  File "/home/cthi/PycharmProjects/fde-etl-pipeline/venv/lib/python3.8/site-packages/pandas/io/common.py", line 737, in get_handle
    check_parent_directory(str(handle))
  File "/home/cthi/PycharmProjects/fde-etl-pipeline/venv/lib/python3.8/site-packages/pandas/io/common.py", line 600, in check_parent_directory
    raise OSError(rf"Cannot save file into a non-existent directory: '{parent}'")
[0m
